Workbook

Sheet Registro de Compras
A1: Semanas | B1: Fecha | C1: Categoría | D1: Producto | E1: Precio (€) | F1: Precio ($) | G1: Tienda | H1: Gasto del día (€) | I1: Gasto del día ($)
A2: 17-22 ago | B2: 45886 | C2: Comida | D2: Jamón | E2: 1 | F2: =E2*23 -> 23 | G2: Carrefour express | H2: =SUMIF(B:B,"17/8/2025",E:E) -> 22.79 | I2: =H2*23 -> 524.17
B3: 45886 | D3: Huevo | E3: 2.75 | F3: =E3*23 -> 63.25 | G3: Carrefour express
B4: 45886 | D4: Pan Caja | E4: 1.15 | F4: =E4*23 -> 26.45 | G4: Carrefour express
B5: 45886 | D5: Cereal | E5: 1.69 | F5: =E5*23 -> 38.87 | G5: Carrefour express
B6: 45886 | D6: Queso | E6: 2.65 | F6: =E6*23 -> 60.95 | G6: Carrefour express
B7: 45886 | D7: Leche de soja | E7: 1.25 | F7: =E7*23 -> 28.75 | G7: Carrefour express
B8: 45886 | D8: Aceite de oliva | E8: 2.7 | F8: =E8*23 -> 62.1 | G8: Carrefour express
B9: 45886 | D9: Agua | E9: 1 | F9: =E9*23 -> 23 | G9: Tienda random
B10: 45886 | D10: Hamburguesa | E10: 6.95 | F10: =E10*23 -> 159.85 | G10: Carls JR
B11: 45886 | C11: Higiene | D11: Jabón de manos | E11: 1.65 | F11: =E11*23 -> 37.95 | G11: Carrefour express
B12: 45887 | C12: Comida | D12: Agua 6 L | E12: 1.16 | F12: =E12*23 -> 26.68 | G12: Mercadona | H12: =SUMIF(B:B,"18/8/2025",E:E) -> 33.92 | I12: =H12*23 -> 780.16
B13: 45887 | D13: Crema de cacahuate | E13: 3.19 | F13: =E13*23 -> 73.37 | G13: Carrefour express
B14: 45887 | D14: Mantequilla | E14: 2.25 | F14: =E14*23 -> 51.75 | G14: Mercadona
B15: 45887 | D15: Salmón con verduras | E15: 5.75 | F15: =E15*23 -> 132.25 | G15: Mercadona
B16: 45887 | D16: Verduras | E16: 2 | F16: =E16*23 -> 46 | G16: Mercadona
B17: 45887 | D17: Pimienta | E17: 1.3 | F17: =E17*23 -> 29.9 | G17: Mercadona
B18: 45887 | D18: Sal de ajo | E18: 1.8 | F18: =E18*23 -> 41.4 | G18: Mercadona
B19: 45887 | D19: Jitomate | E19: 0.76 | F19: =E19*23 -> 17.48 | G19: Aldi
B20: 45887 | D20: Leche de soja | E20: 0.62 | F20: =E20*23 -> 14.26 | G20: Aldi
B21: 45887 | D21: Yogurt | E21: 2.99 | F21: =E21*23 -> 68.77 | G21: Aldi
B22: 45887 | C22: Cosas | D22: Bolsa | E22: 0.35 | F22: =E22*23 -> 8.05 | G22: Aldi
B23: 45887 | D23: Bolsa isotermica | E23: 1.9 | F23: =E23*23 -> 43.7 | G23: Mercadona
B24: 45887 | D24: Taza | E24: 2.95 | F24: =E24*23 -> 67.85 | G24: Culinarium
B25: 45887 | D25: Bowl | E25: 4.95 | F25: =E25*23 -> 113.85 | G25: Culinarium
B26: 45887 | C26: Higiene | D26: Enjuage bocal | E26: 1.95 | F26: =E26*23 -> 44.85 | G26: Carrefour express
B27: 45888 | C27: Comida | D27: Carne | E27: 8.96 | F27: =E27*23 -> 206.08 | G27: Mercadona | H27: =SUMIF(B:B,"19/8/2025",E:E) -> 15.33 | I27: =H27*23 -> 352.59
B28: 45888 | D28: Pollo | E28: 4.75 | F28: =E28*23 -> 109.25 | G28: Mercadona
B29: 45888 | D29: Limón | E29: 0.63 | F29: =E29*23 -> 14.49 | G29: Mercadona
B30: 45888 | D30: Plátano | E30: 0.99 | F30: =E30*23 -> 22.77 | G30: Mercadona
B31: 45889 | C31: Comida | D31: Atún | E31: 5.65 | F31: =E31*23 -> 129.95 | G31: Carrefour Market | H31: =SUMIF(B:B,"20/8/2025",E:E) -> 20.95 | I31: =H31*23 -> 481.85
B32: 45889 | D32: Jamón | E32: 2.89 | F32: =E32*23 -> 66.47 | G32: Carrefour Market
B33: 45889 | D33: Papas | E33: 1.49 | F33: =E33*23 -> 34.27 | G33: Carrefour Market
B34: 45889 | D34: Café | E34: 4.93 | F34: =E34*23 -> 113.39 | G34: Alcampo
B35: 45889 | D35: Huevo | E35: 4.75 | F35: =E35*23 -> 109.25 | G35: Aldi
B36: 45889 | D36: Leche de soja (2) | E36: 1.24 | F36: =E36*23 -> 28.52 | G36: Aldi
B37: 45890 | C37: Comida | D37: Agua (Bezoya) | E37: 2.41 | F37: =E37*23 -> 55.43 | G37: Alcampo | H37: =SUMIF(B:B,"21/8/2025",E:E) -> 19.41 | I37: =H37*23 -> 446.43
B38: 45890 | D38: Pan | E38: 3 | F38: =E38*23 -> 69 | G38: Vivari
B39: 45890 | C39: Servicio | D39: Pase mensual | E39: 14 | F39: =E39*23 -> 322 | G39: Metro
B40: 45891 | C40: Higiene | D40: Detergente ropa | E40: 7.85 | F40: =E40*23 -> 180.55 | G40: Carrefour Market | H40: =SUMIF(B:B,"22/8/2025",E:E) -> 9.45 | I40: =H40*23 -> 217.35
...

Sheet Resumen Semanal
A1: Semana | B1: Presupuesto (€) | C1: Gastado (€) | D1: Gasto Recurrente Esperado(€) | E1: Total proyectado (€) | F1: Disponible (€) | I1: Ahorrado | K1: Gastado Viaje | L1: Ahorrado Final
A2: 17-22 ago | B2: 147 | C2: =SUMIFS('Registro de Compras'!E:E, 'Registro de Compras'!B:B, ">=17/08/2025", 'Registro de Compras'!B:B, "<=22/08/2025") -> 121.85 | D2: ='Productos Recurrentes'!H13 -> 0 | F2: =B2-C2 -> 25.15 | G2: =F2*23 -> 578.45 | I2: =SUM(F2:F23) -> 145.88739 | J2: =I2*23 -> 3355.41 | K2: =L6 -> 126.3 | L2: =I2-K2 -> 19.587391
A3: 23-29 ago | B3: =100 -> 100 | C3: =SUMIFS('Registro de Compras'!E:E, 'Registro de Compras'!B:B, ">=23/08/2025", 'Registro de Compras'!B:B, "<=29/08/2025") -> 92.29 | F3: =B3-C3 -> 7.71 | G3: =F3*23 -> 177.33
A4: 30-5 sept | B4: 100 | C4: =SUMIFS('Registro de Compras'!E:E, 'Registro de Compras'!B:B, ">=30/08/2025", 'Registro de Compras'!B:B, "<=05/09/2025") -> 87.76 | F4: =B4-C4 -> 12.24
A5: 6-12 sept | B5: 100 | C5: =SUMIFS('Registro de Compras'!E:E, 'Registro de Compras'!B:B, ">=06/09/2025", 'Registro de Compras'!B:B, "<=12/09/2025") -> 76.32 | F5: =B5-C5 -> 23.68 | I5: Viajes | L5: Total
A6: 13-19 sept | B6: 100 | C6: =SUMIFS('Registro de Compras'!E:E, 'Registro de Compras'!B:B, ">=13/09/2025", 'Registro de Compras'!B:B, "<=19/09/2025") -> 168.14 | F6: =B6-C6 -> -68.14 | J6: Bus Marbella | K6: 36.9 | L6: =SUM(K6:K9) -> 126.3 | M6: =L6*23 -> 2904.9
A7: 20-26 sept | B7: 100 | C7: =SUMIFS('Registro de Compras'!E:E, 'Registro de Compras'!B:B, ">=20/09/2025", 'Registro de Compras'!B:B, "<=26/09/2025") -> 58.511304 | F7: =B7-C7 -> 41.488696 | J7: Tren Madrid Málaga | K7: 35
A8: 27-3 oct | B8: 100 | C8: =SUMIFS('Registro de Compras'!E:E, 'Registro de Compras'!B:B, ">=27/09/2025", 'Registro de Compras'!B:B, "<=03/10/2025") -> 96.09 | F8: =B8-C8 -> 3.91 | J8: Tren Malaga-Madrid | K8: 22
A9: 4-10 oct | B9: 100 | C9: =SUMIFS('Registro de Compras'!E:E, 'Registro de Compras'!B:B, ">=04/10/2025", 'Registro de Compras'!B:B, "<=10/10/2025") -> 61.61 | F9: =B9-C9 -> 38.39 | J9: Ronda | K9: 32.4
A10: 11-17 oct | B10: 100 | C10: =SUMIFS('Registro de Compras'!E:E, 'Registro de Compras'!B:B, ">=11/10/2025", 'Registro de Compras'!B:B, "<=17/10/2025") -> 87.01 | F10: =B10-C10 -> 12.99
A11: 18-24 oct | B11: 100 | C11: =SUMIFS('Registro de Compras'!E:E, 'Registro de Compras'!B:B, ">=18/10/2025", 'Registro de Compras'!B:B, "<=24/10/2025") -> 68.791304 | F11: =B11-C11 -> 31.208696
A12: 25-31 nov | B12: 100 | C12: =SUMIFS('Registro de Compras'!E:E, 'Registro de Compras'!B:B, ">=25/10/2025", 'Registro de Compras'!B:B, "<=31/10/2025") -> 82.74 | F12: =B12-C12 -> 17.26
A13: 1-7 nov | F13: =B13-C13 -> 0
A14: 8-45 nov | F14: =B14-C14 -> 0
A15: 15-21 nov | F15: =B15-C15 -> 0
A16: 22-28 nov | F16: =B16-C16 -> 0
A17: 29-5 dic | F17: =B17-C17 -> 0
A18: 6-12 dic | F18: =B18-C18 -> 0
A19: 13-19 dic | F19: =B19-C19 -> 0
A20: 20-26 dic | F20: =B20-C20 -> 0
A21: 27-2 ene | F21: =B21-C21 -> 0
A22: 2-9 ene | F22: =B22-C22 -> 0
A23: 10-16 ene | F23: =B23-C23 -> 0

Sheet Productos Recurrentes
B1: Producto | C1: Duración (días) | D1: Última Compra | E1: Fecha fin estimada
A2: Desayuno Cotidiano | B2: Huevo | C2: 7 | D2: =_xlfn.MAXIFS('Registro de Compras'!B:B, 'Registro de Compras'!D:D, 'Productos Recurrentes'!B2) -> 45955 | E2: =D2+C2-1 -> 45961
B3: Jamón | C3: 14 | D3: =_xlfn.MAXIFS('Registro de Compras'!B:B, 'Registro de Compras'!D:D, 'Productos Recurrentes'!B3) -> 45936 | E3: =D3+C3-1 -> 45949
B4: Pan Caja | C4: 7 | D4: =_xlfn.MAXIFS('Registro de Compras'!B:B, 'Registro de Compras'!D:D, 'Productos Recurrentes'!B4) -> 45895 | E4: =D4+C4-1 -> 45901
B5: Crema de cacahuate | C5: 14 | D5: =_xlfn.MAXIFS('Registro de Compras'!B:B, 'Registro de Compras'!D:D, 'Productos Recurrentes'!B5) -> 45941 | E5: =D5+C5-1 -> 45954
B6: Plátano | C6: 4 | D6: =_xlfn.MAXIFS('Registro de Compras'!B:B, 'Registro de Compras'!D:D, 'Productos Recurrentes'!B6) -> 45915 | E6: =D6+C6-1 -> 45918
B7: Café | C7: 15 | D7: =_xlfn.MAXIFS('Registro de Compras'!B:B, 'Registro de Compras'!D:D, 'Productos Recurrentes'!B7) -> 45904 | E7: =D7+C7-1 -> 45918
B8: Jitomate | C8: 14 | D8: =_xlfn.MAXIFS('Registro de Compras'!B:B, 'Registro de Compras'!D:D, 'Productos Recurrentes'!B8) -> 45955 | E8: =D8+C8-1 -> 45968
B9: Champiñiones | C9: 14 | D9: =_xlfn.MAXIFS('Registro de Compras'!B:B, 'Registro de Compras'!D:D, 'Productos Recurrentes'!B9) -> 45944 | E9: =D9+C9-1 -> 45957
B10: Espinaca | C10: 7 | D10: =_xlfn.MAXIFS('Registro de Compras'!B:B, 'Registro de Compras'!D:D, 'Productos Recurrentes'!B10) -> 45951 | E10: =D10+C10-1 -> 45957
B11: Agua (Bezoya) | C11: 7 | D11: =_xlfn.MAXIFS('Registro de Compras'!B:B, 'Registro de Compras'!D:D, 'Productos Recurrentes'!B11) -> 45890 | E11: =D11+C11-1 -> 45896
B12: Leche de soja (2) | C12: 6 | D12: =_xlfn.MAXIFS('Registro de Compras'!B:B, 'Registro de Compras'!D:D, 'Productos Recurrentes'!B12) -> 45954 | E12: =D12+C12-1 -> 45959
A13: Comida | B13: Carne | C13: 7 | D13: =_xlfn.MAXIFS('Registro de Compras'!B:B, 'Registro de Compras'!D:D, 'Productos Recurrentes'!B13) -> 45915 | E13: =D13+C13-1 -> 45921
B14: Pollo | C14: 7 | D14: =_xlfn.MAXIFS('Registro de Compras'!B:B, 'Registro de Compras'!D:D, 'Productos Recurrentes'!B14) -> 45955 | E14: =D14+C14-1 -> 45961
B15: Pescado | C15: 7 | D15: =_xlfn.MAXIFS('Registro de Compras'!B:B, 'Registro de Compras'!D:D, 'Productos Recurrentes'!B15) -> 45920 | E15: =D15+C15-1 -> 45926
B16: Verduras | C16: 14 | D16: =_xlfn.MAXIFS('Registro de Compras'!B:B, 'Registro de Compras'!D:D, 'Productos Recurrentes'!B16) -> 45920 | E16: =D16+C16-1 -> 45933
B17: Papas | C17: 7 | D17: =_xlfn.MAXIFS('Registro de Compras'!B:B, 'Registro de Compras'!D:D, 'Productos Recurrentes'!B17) -> 45948 | E17: =D17+C17-1 -> 45954
A18: Cena | B18: Yogurt | C18: 7 | D18: =_xlfn.MAXIFS('Registro de Compras'!B:B, 'Registro de Compras'!D:D, 'Productos Recurrentes'!B18) -> 45955 | E18: =D18+C18-1 -> 45961
B19: Cereal | C19: 30 | D19: =_xlfn.MAXIFS('Registro de Compras'!B:B, 'Registro de Compras'!D:D, 'Productos Recurrentes'!B19) -> 45951 | E19: =D19+C19-1 -> 45980
A20: Higiene | B20: Jabón de manos | C20: 60 | D20: =_xlfn.MAXIFS('Registro de Compras'!B:B, 'Registro de Compras'!D:D, 'Productos Recurrentes'!B20) -> 45936 | E20: =D20+C20-1 -> 45995
B21: Detergente ropa | C21: 90 | D21: =_xlfn.MAXIFS('Registro de Compras'!B:B, 'Registro de Compras'!D:D, 'Productos Recurrentes'!B21) -> 45891 | E21: =D21+C21-1 -> 45980
B22: Enjuage bocal | C22: 30 | D22: =_xlfn.MAXIFS('Registro de Compras'!B:B, 'Registro de Compras'!D:D, 'Productos Recurrentes'!B22) -> 45887 | E22: =D22+C22-1 -> 45916

Sheet Comidas
A1: Opcion A
B2: Lunes | C2: Martes | D2: Miércoles | E2: Jueves | F2: Viernes | G2: Sábado | H2: Domingo
A3: Desayuno | B3: Huevo con espinaca | C3: Huevo con espinaca | D3: Huevo con espinaca | E3: Huevo con jamón | F3: Huevo con jamón | G3: Huevo con jamón | H3: Pan francés | I3: Aproximado:
A4: Snack | B4: Pan tostado | C4: Yogurt con cereal | D4: Pan tostado | E4: Yogurt con cereal | F4: Yogurt con cereal | G4: Pan tostado | H4: Yogut con cereal
A5: Comida | B5: Pollo al ajillo con arroz y papas | C5: Pescado con pimienton arroz y papas | D5: Pollo con salsa de tomate con arroz y papas | E5: Pescado curry arroz y papas | F5: Pollo con salsa de tomate, arroz y papas | G5: Pescado con pimienton arroz y papas | H5: Salmón con pure de papas y verduras
A6: Cena | B6: Hot cakes | C6: Lentejas | D6: Hot cakes | E6: Lentejas | F6: Hot cakes | G6: Lentejas | H6: Hot cakes
A8: Opcion A
B9: Lunes | C9: Martes | D9: Miércoles | E9: Jueves | F9: Viernes | G9: Sábado | H9: Domingo
A10: Desayuno | B10: Huevo con champiiñones | C10: Huevo con champiiñones | D10: Huevo con champiñiones | E10: Huevo con jamón | F10: Huevo con jamón | G10: Huevo con jamón | H10: Pan francés
A11: Snack | B11: Pan tostado | C11: Yogurt con cereal | D11: Pan tostado | E11: Yogurt con cereal | F11: Yogurt con cereal | G11: Pan tostado | H11: Yogut con cereal
A12: Comida | B12: Pollo con paprica y limon, arroz y papas | C12: Pescado salsa de tomate o con arroz y papas | D12: Pollo hierbas y limón con arroz y papas | E12: Pescado con ajo y pimienta arroz y papas | F12: Pollo con paprica y limon, arroz y papas | G12: Pescado con con limón y ajo arroz y papas | H12: Salmón con pure de papas y verduras
A13: Cena | B13: Hot cakes | C13: Garbanzos | D13: Hot cakes | E13: Garbanzos | F13: Hot cakes | G13: Garbanzos | H13: Hot cakes
A15: Opcion A
B16: Lunes | C16: Martes | D16: Miércoles | E16: Jueves | F16: Viernes | G16: Sábado | H16: Domingo
A17: Desayuno | B17: Huevo con jitomate | C17: Huevo con jitomate | D17: Huevo con jitomate | E17: Huevo con jamón | F17: Huevo con jamón | G17: Huevo con jamón | H17: Pan francés
A18: Snack | B18: Pan tostado | C18: Yogurt con cereal | D18: Pan tostado | E18: Yogurt con cereal | F18: Yogurt con cereal | G18: Pan tostado | H18: Yogut con cereal
A19: Comida | B19: Pollo con curry, arroz y papas | C19: Pescado con oregano arroz y papas | D19: Pollo pimienta-limón, con arroz y papas | E19: Pescado con soja arroz y papas | F19: Pollo con curry, arroz y papas | G19: Pescado con oregano arroz y papas | H19: Salmón con pure de papas y verduras
A20: Cena | B20: Hot cakes | C20: Garbanzos | D20: Hot cakes | E20: Garbanzos | F20: Hot cakes | G20: Garbanzos | H20: Hot cakes
